[2025-02-19T18:55:22.096+0000] {local_task_job_runner.py:123} INFO - ::group::Pre task execution logs
[2025-02-19T18:55:22.105+0000] {taskinstance.py:2614} INFO - Dependencies all met for dep_context=non-requeueable deps ti=<TaskInstance: dag_yfinance.create_postgres_table scheduled__2025-02-19T18:54:00+00:00 [queued]>
[2025-02-19T18:55:22.109+0000] {taskinstance.py:2614} INFO - Dependencies all met for dep_context=requeueable deps ti=<TaskInstance: dag_yfinance.create_postgres_table scheduled__2025-02-19T18:54:00+00:00 [queued]>
[2025-02-19T18:55:22.110+0000] {taskinstance.py:2867} INFO - Starting attempt 1 of 6
[2025-02-19T18:55:22.116+0000] {taskinstance.py:2890} INFO - Executing <Task(SQLExecuteQueryOperator): create_postgres_table> on 2025-02-19 18:54:00+00:00
[2025-02-19T18:55:22.122+0000] {standard_task_runner.py:104} INFO - Running: ['***', 'tasks', 'run', 'dag_yfinance', 'create_postgres_table', 'scheduled__2025-02-19T18:54:00+00:00', '--job-id', '9', '--raw', '--subdir', 'DAGS_FOLDER/DAG1.py', '--cfg-path', '/tmp/tmppn8grl30']
[2025-02-19T18:55:22.122+0000] {logging_mixin.py:190} WARNING - /home/***/.local/lib/python3.12/site-packages/***/task/task_runner/standard_task_runner.py:70 DeprecationWarning: This process (pid=2838) is multi-threaded, use of fork() may lead to deadlocks in the child.
[2025-02-19T18:55:22.123+0000] {standard_task_runner.py:105} INFO - Job 9: Subtask create_postgres_table
[2025-02-19T18:55:22.123+0000] {standard_task_runner.py:72} INFO - Started process 2840 to run task
[2025-02-19T18:55:22.146+0000] {task_command.py:467} INFO - Running <TaskInstance: dag_yfinance.create_postgres_table scheduled__2025-02-19T18:54:00+00:00 [running]> on host 07747019ad3d
[2025-02-19T18:55:22.179+0000] {taskinstance.py:3134} INFO - Exporting env vars: AIRFLOW_CTX_DAG_OWNER='admin' AIRFLOW_CTX_DAG_ID='dag_yfinance' AIRFLOW_CTX_TASK_ID='create_postgres_table' AIRFLOW_CTX_EXECUTION_DATE='2025-02-19T18:54:00+00:00' AIRFLOW_CTX_TRY_NUMBER='1' AIRFLOW_CTX_DAG_RUN_ID='scheduled__2025-02-19T18:54:00+00:00'
[2025-02-19T18:55:22.180+0000] {logging_mixin.py:190} INFO - Task instance is in running state
[2025-02-19T18:55:22.180+0000] {logging_mixin.py:190} INFO -  Previous state of the Task instance: queued
[2025-02-19T18:55:22.180+0000] {logging_mixin.py:190} INFO - Current task name:create_postgres_table state:running start_date:2025-02-19 18:55:22.106289+00:00
[2025-02-19T18:55:22.181+0000] {logging_mixin.py:190} INFO - Dag name:dag_yfinance and current dag run status:running
[2025-02-19T18:55:22.181+0000] {taskinstance.py:732} INFO - ::endgroup::
[2025-02-19T18:55:22.181+0000] {sql.py:295} INFO - Executing: 
            create table if not exists stock_data (
                dt timestamp,
                stock_symbol character varying,
                open_price double precision,
                close_price double precision,
                primary key (dt, stock_symbol)
            )
        
[2025-02-19T18:55:22.184+0000] {base.py:84} INFO - Retrieving connection 'postgres_localhost'
[2025-02-19T18:55:22.190+0000] {base.py:84} INFO - Retrieving connection 'postgres_localhost'
[2025-02-19T18:55:22.195+0000] {sql.py:511} INFO - Running statement: 
            create table if not exists stock_data (
                dt timestamp,
                stock_symbol character varying,
                open_price double precision,
                close_price double precision,
                primary key (dt, stock_symbol)
            )
        , parameters: None
[2025-02-19T18:55:22.217+0000] {taskinstance.py:3313} ERROR - Task failed with exception
Traceback (most recent call last):
  File "/home/airflow/.local/lib/python3.12/site-packages/airflow/models/taskinstance.py", line 768, in _execute_task
    result = _execute_callable(context=context, **execute_callable_kwargs)
             ^^^^^^^^^^^^^^^^^^^^^^^^^^^^^^^^^^^^^^^^^^^^^^^^^^^^^^^^^^^^^
  File "/home/airflow/.local/lib/python3.12/site-packages/airflow/models/taskinstance.py", line 734, in _execute_callable
    return ExecutionCallableRunner(
           ^^^^^^^^^^^^^^^^^^^^^^^^
  File "/home/airflow/.local/lib/python3.12/site-packages/airflow/utils/operator_helpers.py", line 252, in run
    return self.func(*args, **kwargs)
           ^^^^^^^^^^^^^^^^^^^^^^^^^^
  File "/home/airflow/.local/lib/python3.12/site-packages/airflow/models/baseoperator.py", line 424, in wrapper
    return func(self, *args, **kwargs)
           ^^^^^^^^^^^^^^^^^^^^^^^^^^^
  File "/home/airflow/.local/lib/python3.12/site-packages/airflow/providers/common/sql/operators/sql.py", line 301, in execute
    output = hook.run(
             ^^^^^^^^^
  File "/home/airflow/.local/lib/python3.12/site-packages/airflow/providers/common/sql/hooks/sql.py", line 467, in run
    self._run_command(cur, sql_statement, parameters)
  File "/home/airflow/.local/lib/python3.12/site-packages/airflow/providers/common/sql/hooks/sql.py", line 516, in _run_command
    cur.execute(sql_statement)
psycopg2.errors.UniqueViolation: duplicate key value violates unique constraint "pg_type_typname_nsp_index"
DETAIL:  Key (typname, typnamespace)=(stock_data, 2200) already exists.

[2025-02-19T18:55:22.223+0000] {logging_mixin.py:190} INFO - Task instance in failure state
[2025-02-19T18:55:22.223+0000] {logging_mixin.py:190} INFO - Task start:2025-02-19 18:55:22.106289+00:00 end:2025-02-19 18:55:22.222823+00:00 duration:0.116534
[2025-02-19T18:55:22.223+0000] {logging_mixin.py:190} INFO - Task:<Task(SQLExecuteQueryOperator): create_postgres_table> dag:<DAG: dag_yfinance> dagrun:<DagRun dag_yfinance @ 2025-02-19 18:54:00+00:00: scheduled__2025-02-19T18:54:00+00:00, state:running, queued_at: 2025-02-19 18:55:21.481360+00:00. externally triggered: False>
[2025-02-19T18:55:22.223+0000] {logging_mixin.py:190} INFO - Failure caused by duplicate key value violates unique constraint "pg_type_typname_nsp_index"
DETAIL:  Key (typname, typnamespace)=(stock_data, 2200) already exists.
[2025-02-19T18:55:22.223+0000] {taskinstance.py:1226} INFO - Marking task as UP_FOR_RETRY. dag_id=dag_yfinance, task_id=create_postgres_table, run_id=scheduled__2025-02-19T18:54:00+00:00, execution_date=20250219T185400, start_date=20250219T185522, end_date=20250219T185522
[2025-02-19T18:55:22.234+0000] {taskinstance.py:341} INFO - ::group::Post task execution logs
[2025-02-19T18:55:22.234+0000] {standard_task_runner.py:124} ERROR - Failed to execute job 9 for task create_postgres_table (duplicate key value violates unique constraint "pg_type_typname_nsp_index"
DETAIL:  Key (typname, typnamespace)=(stock_data, 2200) already exists.
; 2840)
Traceback (most recent call last):
  File "/home/airflow/.local/lib/python3.12/site-packages/airflow/task/task_runner/standard_task_runner.py", line 117, in _start_by_fork
    ret = args.func(args, dag=self.dag)
          ^^^^^^^^^^^^^^^^^^^^^^^^^^^^^
  File "/home/airflow/.local/lib/python3.12/site-packages/airflow/cli/cli_config.py", line 49, in command
    return func(*args, **kwargs)
           ^^^^^^^^^^^^^^^^^^^^^
  File "/home/airflow/.local/lib/python3.12/site-packages/airflow/utils/cli.py", line 116, in wrapper
    return f(*args, **kwargs)
           ^^^^^^^^^^^^^^^^^^
  File "/home/airflow/.local/lib/python3.12/site-packages/airflow/cli/commands/task_command.py", line 483, in task_run
    task_return_code = _run_task_by_selected_method(args, _dag, ti)
                       ^^^^^^^^^^^^^^^^^^^^^^^^^^^^^^^^^^^^^^^^^^^^
  File "/home/airflow/.local/lib/python3.12/site-packages/airflow/cli/commands/task_command.py", line 256, in _run_task_by_selected_method
    return _run_raw_task(args, ti)
           ^^^^^^^^^^^^^^^^^^^^^^^
  File "/home/airflow/.local/lib/python3.12/site-packages/airflow/cli/commands/task_command.py", line 341, in _run_raw_task
    return ti._run_raw_task(
           ^^^^^^^^^^^^^^^^^
  File "/home/airflow/.local/lib/python3.12/site-packages/airflow/utils/session.py", line 97, in wrapper
    return func(*args, session=session, **kwargs)
           ^^^^^^^^^^^^^^^^^^^^^^^^^^^^^^^^^^^^^^
  File "/home/airflow/.local/lib/python3.12/site-packages/airflow/models/taskinstance.py", line 3006, in _run_raw_task
    return _run_raw_task(
           ^^^^^^^^^^^^^^
  File "/home/airflow/.local/lib/python3.12/site-packages/airflow/models/taskinstance.py", line 274, in _run_raw_task
    TaskInstance._execute_task_with_callbacks(
  File "/home/airflow/.local/lib/python3.12/site-packages/airflow/models/taskinstance.py", line 3161, in _execute_task_with_callbacks
    result = self._execute_task(context, task_orig)
             ^^^^^^^^^^^^^^^^^^^^^^^^^^^^^^^^^^^^^^
  File "/home/airflow/.local/lib/python3.12/site-packages/airflow/models/taskinstance.py", line 3185, in _execute_task
    return _execute_task(self, context, task_orig)
           ^^^^^^^^^^^^^^^^^^^^^^^^^^^^^^^^^^^^^^^
  File "/home/airflow/.local/lib/python3.12/site-packages/airflow/models/taskinstance.py", line 768, in _execute_task
    result = _execute_callable(context=context, **execute_callable_kwargs)
             ^^^^^^^^^^^^^^^^^^^^^^^^^^^^^^^^^^^^^^^^^^^^^^^^^^^^^^^^^^^^^
  File "/home/airflow/.local/lib/python3.12/site-packages/airflow/models/taskinstance.py", line 734, in _execute_callable
    return ExecutionCallableRunner(
           ^^^^^^^^^^^^^^^^^^^^^^^^
  File "/home/airflow/.local/lib/python3.12/site-packages/airflow/utils/operator_helpers.py", line 252, in run
    return self.func(*args, **kwargs)
           ^^^^^^^^^^^^^^^^^^^^^^^^^^
  File "/home/airflow/.local/lib/python3.12/site-packages/airflow/models/baseoperator.py", line 424, in wrapper
    return func(self, *args, **kwargs)
           ^^^^^^^^^^^^^^^^^^^^^^^^^^^
  File "/home/airflow/.local/lib/python3.12/site-packages/airflow/providers/common/sql/operators/sql.py", line 301, in execute
    output = hook.run(
             ^^^^^^^^^
  File "/home/airflow/.local/lib/python3.12/site-packages/airflow/providers/common/sql/hooks/sql.py", line 467, in run
    self._run_command(cur, sql_statement, parameters)
  File "/home/airflow/.local/lib/python3.12/site-packages/airflow/providers/common/sql/hooks/sql.py", line 516, in _run_command
    cur.execute(sql_statement)
psycopg2.errors.UniqueViolation: duplicate key value violates unique constraint "pg_type_typname_nsp_index"
DETAIL:  Key (typname, typnamespace)=(stock_data, 2200) already exists.

[2025-02-19T18:55:22.263+0000] {local_task_job_runner.py:266} INFO - Task exited with return code 1
[2025-02-19T18:55:22.274+0000] {taskinstance.py:3901} INFO - 0 downstream tasks scheduled from follow-on schedule check
[2025-02-19T18:55:22.275+0000] {local_task_job_runner.py:245} INFO - ::endgroup::
